Workbook

Sheet 使い方
A1: このファイルの使い方
B2: このExcelを編集してGitHubの data フォルダにアップロードすると、自動でサイトのデータ（ai-tools.json）に変換されます。
A4: 編集のルール
A5: シート名・見出し | B5: 「AIツール一覧」シートの名前と、1行目の見出しは変えないでください。
A6: AIを追加する | B6: 一番下の空いている行に入力します。行の順番がサイトでの並び順になります。
A7: AIを削除する | B7: 行ごと削除します（行を右クリック →「削除」）。
A8: カテゴリ | B8: 「カテゴリ一覧」シートにある名前を、「、」で区切って入力します。例：画像作成、画像編集
A9: 強み | B9: 1つのセルに4項目を入れます。項目の間は Alt＋Enter で改行します。
A10: 料金タイプ | B10: セルを選ぶと出る ▼ から選びます（完全無料／無料枠あり／トライアルのみ）。
A11: 無料利用範囲 | B11: 空欄にすると、料金タイプに合わせた標準の文が自動で入ります。
A12: 日本語対応 | B12: ▼ から選びます。◯＝日本語の画面あり、△＝日本語で入力・出力できる、×＝英語中心
A13: 登録不要 | B13: アカウントなしで試せる場合だけ ◯ を選びます。それ以外は空欄。
A14: TOP10順位 | B14: よく使われるAIのTOP10に入れる場合だけ、1〜10の順位を入れます。カテゴリへのTOP10の追加は自動です。
A16: サイトに反映する手順
A17: 1 | B17: このファイルを保存します（ファイル名は ai-tools.xlsx のまま）。
A18: 2 | B18: GitHubのリポジトリで data フォルダを開き、「Add file」→「Upload files」でこのファイルをアップロードして「Commit changes」を押します。
A19: 3 | B19: 「Actions」タブで「ExcelからJSONに変換」が緑の ✓ になれば完了です。数分でサイトに反映されます。
A20: 4 | B20: 赤い ✕ になった場合は、入力ミスがあります。✕ をクリックすると、何行目のどこが間違っているかが表示されます。サイトは前の状態のまま壊れません。

Sheet AIツール一覧
A1: AI名 | B1: URL | C1: 国 | D1: 開発企業 | E1: カテゴリ | F1: 強み | G1: 料金タイプ | H1: 無料利用範囲 | I1: 日本語対応 | J1: 登録不要 | K1: TOP10順位
A2: ChatGPT | B2: https://chatgpt.com | C2: アメリカ | D2: OpenAI | E2: よく使われるAIのTOP10、パーソナルアシスタント、情報検索・リサーチ、学習・教育、テキスト生成・AI執筆、画像作成、Excel・事務作業 | F2: 会話・文章作成・要約・翻訳を1つで 画像生成や画像の読み取りに対応 PDF・Excelを読み込んで分析 スマホアプリで音声会話 | G2: 無料枠あり | H2: 無料プランあり（回数・機能に制限） | I2: ◯ | J2: ◯ | K2: 1
A3: Claude | B3: https://claude.ai | C3: アメリカ | D3: Anthropic | E3: よく使われるAIのTOP10、パーソナルアシスタント、ノーコードでアプリ作成、要約と構造化、テキスト生成・AI執筆、データ分析・予測、Excel・事務作業 | F3: 長い文書や資料を一度に読み込める 自然で丁寧な日本語の文章 プログラムの作成・修正が得意 画面上で動くアプリや図を作成 | G3: 無料枠あり | H3: 無料プランあり（回数・機能に制限） | I3: ◯ | K3: 3
A4: Google Gemini | B4: https://gemini.google.com | C4: アメリカ | D4: Google | E4: よく使われるAIのTOP10、パーソナルアシスタント、情報検索・リサーチ、画像作成、データ分析・予測、Excel・事務作業 | F4: Gmail・ドライブ・YouTubeと連携 Google検索で最新情報を反映 画像・動画生成（Imagen・Veo） Deep Researchで調査レポート | G4: 無料枠あり | H4: 無料プランあり（回数・機能に制限） | I4: ◯ | K4: 2
A5: Microsoft Copilot | B5: https://copilot.microsoft.com | C5: アメリカ | D5: Microsoft | E5: よく使われるAIのTOP10、パーソナルアシスタント、情報検索・リサーチ、画像作成、Excel・事務作業 | F5: Bing検索の結果を出典付きで回答 無料で画像生成も可能 Windows・Edgeに標準搭載 音声で会話できる | G5: 完全無料 | H5: Microsoftアカウントで無料利用可 | I5: ◯ | J5: ◯ | K5: 7
A6: Meta AI | B6: https://www.meta.ai | C6: アメリカ | D6: Meta | E6: よく使われるAIのTOP10、パーソナルアシスタント、画像作成 | F6: Instagram・WhatsApp・Messengerから使える 画像生成と画像編集 会話は無料 Llamaモデルを使用 | G6: 完全無料 | H6: 無料で利用可能 | I6: △ | K6: 10
A7: Grok | B7: https://grok.com | C7: アメリカ | D7: xAI | E7: よく使われるAIのTOP10、パーソナルアシスタント、情報検索・リサーチ、画像作成 | F7: X（旧Twitter）の投稿をもとに最新の話題を回答 画像生成・画像編集 Webアプリとスマホアプリあり 深い推論モード | G7: 無料枠あり | H7: 無料プランあり（回数・機能に制限） | I7: ◯ | K7: 5
A8: Perplexity | B8: https://www.perplexity.ai | C8: アメリカ | D8: Perplexity AI | E8: よく使われるAIのTOP10、情報検索・リサーチ、論文・リサーチ分析 | F8: 回答ごとに参照元のリンクを表示 複数サイトをまとめて要約 論文・ニュースに絞った検索 深掘り調査（Research） | G8: 無料枠あり | H8: 無料プランあり（回数・機能に制限） | I8: ◯ | J8: ◯ | K8: 6
A9: DeepSeek | B9: https://chat.deepseek.com | C9: 中国 | D9: DeepSeek | E9: よく使われるAIのTOP10、パーソナルアシスタント、開発者向けツール、情報検索・リサーチ、学習・教育 | F9: 数学・論理の推論に強い プログラム生成が得意 Web版・アプリとも無料 モデルがオープン公開 | G9: 完全無料 | H9: 無料で利用可能 | I9: △ | K9: 4
A10: Qwen Chat（通义千问） | B10: https://chat.qwen.ai | C10: 中国 | D10: Alibaba | E10: パーソナルアシスタント、情報検索・リサーチ、画像作成 | F10: 長い文書の読解 画像・動画の生成 Webページ・アプリの作成 多言語に対応（日本語入力可） | G10: 完全無料 | H10: 無料で利用可能 | I10: △
A11: Kimi | B11: https://www.kimi.com | C11: 中国 | D11: Moonshot AI | E11: パーソナルアシスタント、要約と構造化、情報検索・リサーチ | F11: とても長い文書・複数ファイルを読める Web検索で調べてまとめる スライド資料の作成 推論モデルを無料で利用 | G11: 完全無料 | H11: 無料で利用可能 | I11: △
A12: Doubao（豆包） | B12: https://www.doubao.com | C12: 中国 | D12: ByteDance | E12: パーソナルアシスタント、学習・教育 | F12: 中国で利用者が多い対話AI 音声で自然に会話 画像生成・写真加工 文章作成・翻訳 | G12: 完全無料 | H12: 無料で利用可能 | I12: △
A13: ERNIE Bot（文心一言） | B13: https://yiyan.baidu.com | C13: 中国 | D13: Baidu | E13: パーソナルアシスタント、情報検索・リサーチ | F13: 百度（Baidu）検索と連携 中国語の文章・知識に強い 画像生成 個人利用は無料 | G13: 完全無料 | H13: 無料で利用可能 | I13: △
A14: 智谱清言（ChatGLM） | B14: https://chatglm.cn | C14: 中国 | D14: Zhipu AI | E14: パーソナルアシスタント、情報検索・リサーチ | F14: 清華大学発のGLMモデル 中国語の会話・文章作成 Web検索とファイル読解 エージェント機能 | G14: 完全無料 | H14: 無料で利用可能 | I14: △
A15: 腾讯元宝（Yuanbao） | B15: https://yuanbao.tencent.com | C15: 中国 | D15: Tencent | E15: パーソナルアシスタント、情報検索・リサーチ | F15: WeChat公式アカウントの記事を検索 DeepSeekとHunyuanを切り替え ファイル要約 無料で利用 | G15: 完全無料 | H15: 無料で利用可能 | I15: △
A16: 讯飞星火（iFlytek Spark） | B16: https://xinghuo.xfyun.cn | C16: 中国 | D16: iFlytek | E16: パーソナルアシスタント、言語・翻訳 | F16: 音声認識・音声合成の技術に強い 中国語と英語の翻訳 教育・事務向け機能 文章作成 | G16: 完全無料 | H16: 無料で利用可能 | I16: △
A17: Le Chat | B17: https://chat.mistral.ai | C17: フランス | D17: Mistral AI | E17: パーソナルアシスタント、情報検索・リサーチ | F17: 応答がとても速い Web検索と出典表示 画像生成 ヨーロッパのプライバシー基準 | G17: 無料枠あり | H17: 無料プランあり（回数・機能に制限） | I17: △
A18: Poe | B18: https://poe.com | C18: アメリカ | D18: Quora | E18: パーソナルアシスタント | F18: ChatGPT・Claude・Geminiなどを1つの画面で切替 回答を比べやすい 自分専用ボットを作成 スマホアプリ | G18: 無料枠あり | H18: 無料プランあり（回数・機能に制限） | I18: ◯
A19: Pi | B19: https://pi.ai | C19: アメリカ | D19: Inflection AI | E19: 悩み相談、パーソナルアシスタント | F19: 共感を大切にした話し相手 やさしい口調で雑談・相談 音声で会話できる 登録なしでも試せる | G19: 完全無料 | H19: 無料で利用可能 | I19: △
A20: You.com | B20: https://you.com | C20: アメリカ | D20: You.com | E20: 情報検索・リサーチ | F20: AI検索と出典表示 調査モード（Research） 複数のAIモデルを選択 ファイルを読み込んで質問 | G20: 無料枠あり | H20: 無料プランあり（回数・機能に制限） | I20: △ | J20: ◯
A21: Genspark | B21: https://www.genspark.ai | C21: アメリカ | D21: Genspark | E21: 情報検索・リサーチ、パーソナルアシスタント | F21: 検索結果をまとめたページを自動作成 スライド・表・資料の作成 電話予約などのエージェント 複数AIを組み合わせ | G21: 無料枠あり | H21: 無料プランあり（回数・機能に制限） | I21: ◯
A22: Felo | B22: https://felo.ai | C22: 日本 | D22: Sparticle | E22: 情報検索・リサーチ、日本語特化 | F22: 日本発のAI検索 日本語で出典付き回答 検索結果からスライド・マインドマップを作成 多言語の情報をまとめて翻訳 | G22: 無料枠あり | H22: 無料プランあり（回数・機能に制限） | I22: ◯
A23: Manus | B23: https://manus.im | C23: シンガポール | D23: Butterfly Effect | E23: パーソナルアシスタント、タスクの自動化（RPA連携） | F23: 指示を出すと自分で調べて作業を進める レポート・Webサイトを作成 作業の過程を見られる 複数ステップのタスクを代行 | G23: 無料枠あり | H23: 無料プランあり（回数・機能に制限） | I23: ◯
A24: Monica | B24: https://monica.im | C24: シンガポール | D24: Butterfly Effect | E24: パーソナルアシスタント、要約と構造化 | F24: ブラウザ拡張で閲覧中のページを要約 YouTube動画の要約 翻訳・文章の書き直し 複数のAIモデルを利用 | G24: 無料枠あり | H24: 無料プランあり（回数・機能に制限） | I24: ◯
A25: GigaChat | B25: https://giga.chat | C25: ロシア | D25: Sber | E25: パーソナルアシスタント | F25: ロシア語の会話・文章作成 画像生成（Kandinsky） ロシアの銀行Sber製 無料で利用 | G25: 完全無料 | H25: 無料で利用可能 | I25: ×
A26: Alice（YandexGPT） | B26: https://alice.yandex.ru | C26: ロシア | D26: Yandex | E26: パーソナルアシスタント | F26: ロシア語の音声アシスタント Yandex検索と連携 スマートスピーカー対応 文章作成 | G26: 完全無料 | H26: 無料で利用可能 | I26: ×
A27: Wrtn（リートン） | B27: https://wrtn.ai | C27: 韓国 | D27: Wrtn Technologies | E27: パーソナルアシスタント、テキスト生成・AI執筆 | F27: 最新のAIモデルを無料で利用 日本語画面あり 画像生成 用途別のAIツール集 | G27: 完全無料 | H27: 無料で利用可能 | I27: ◯
A28: Brave Leo | B28: https://brave.com/leo/ | C28: アメリカ | D28: Brave | E28: パーソナルアシスタント、情報検索・リサーチ | F28: Braveブラウザに内蔵 閲覧中のページや動画を要約 会話履歴を保存しない設計 アカウントなしで利用可 | G28: 無料枠あり | H28: 無料プランあり（回数・機能に制限） | I28: ◯ | J28: ◯
A29: 秘塔AI搜索（Metaso） | B29: https://metaso.cn | C29: 中国 | D29: 秘塔科技 | E29: 情報検索・リサーチ | F29: 広告のないAI検索 回答をマインドマップで整理 学術論文の検索 中国語の情報に強い | G29: 完全無料 | H29: 無料で利用可能 | I29: △
A30: Skywork | B30: https://skywork.ai | C30: シンガポール | D30: Skywork AI（Kunlun Tech） | E30: 情報検索・リサーチ、パーソナルアシスタント | F30: 調べものをまとめてレポート化 スライド・表・Webページを生成 複数のエージェントで作業 出典付き | G30: 無料枠あり | H30: 無料プランあり（回数・機能に制限） | I30: △
A31: Kagi | B31: https://kagi.com | C31: アメリカ | D31: Kagi | E31: 情報検索・リサーチ | F31: 広告・追跡のない検索エンジン 検索結果のAI要約 好きなサイトを優先・除外できる お試し後は有料 | G31: トライアルのみ | H31: お試し検索回数のみ（継続は有料） | I31: ×
A32: Liner | B32: https://liner.com | C32: 韓国 | D32: Liner | E32: 情報検索・リサーチ、論文・リサーチ分析 | F32: 信頼できる出典を優先して回答 論文検索と引用表示 Webページのハイライト保存 日本語で利用可 | G32: 無料枠あり | H32: 無料プランあり（回数・機能に制限） | I32: ◯
A33: HyperWrite | B33: https://www.hyperwriteai.com | C33: アメリカ | D33: OthersideAI | E33: テキスト生成・AI執筆、パーソナルアシスタント | F33: 文章の続きを予測して書く ブラウザ操作を代行するエージェント 調査・要約 メール作成 | G33: 無料枠あり | H33: 無料プランあり（回数・機能に制限） | I33: △
A34: Llama | B34: https://www.llama.com | C34: アメリカ | D34: Meta | E34: 開発者向けツール | F34: Meta公開の代表的なオープンモデル PCやサーバーで動かせる 自由にカスタマイズ可能 商用利用も可（条件あり） | G34: 完全無料 | H34: 無料で利用可能 | I34: ×
A35: Gemma | B35: https://ai.google.dev/gemma | C35: アメリカ | D35: Google | E35: 開発者向けツール | F35: Google製の軽量オープンモデル 一般的なPCでも動作 画像も理解できる版あり スマホ向けの小型版 | G35: 完全無料 | H35: 無料で利用可能 | I35: ×
A36: Phi | B36: https://azure.microsoft.com/ja-jp/products/phi | C36: アメリカ | D36: Microsoft | E36: 開発者向けツール | F36: Microsoft製の小型モデル 少ないメモリで動く 推論・数学が得意 オープン公開 | G36: 完全無料 | H36: 無料で利用可能 | I36: ×
A37: OLMo | B37: https://allenai.org/olmo | C37: アメリカ | D37: Allen Institute for AI | E37: 開発者向けツール、論文・リサーチ分析 | F37: 学習データ・学習方法まで完全公開 研究・教育向け 自分で再学習できる 非営利団体が開発 | G37: 完全無料 | H37: 無料で利用可能 | I37: △
A38: Falcon | B38: https://falconllm.tii.ae | C38: アラブ首長国連邦 | D38: TII | E38: 開発者向けツール | F38: UAEの研究所が開発 オープンモデル アラビア語など多言語 小型〜大型まで複数サイズ | G38: 完全無料 | H38: 無料で利用可能 | I38: ×
A39: EXAONE | B39: https://www.lgresearch.ai | C39: 韓国 | D39: LG AI Research | E39: 開発者向けツール | F39: 韓国LGの研究所が開発 韓国語と英語に強い 推論性能が高い オープンモデル公開 | G39: 完全無料 | H39: 無料で利用可能 | I39: ×
A40: Swallow | B40: https://swallow-llm.github.io | C40: 日本 | D40: 東京科学大学 | E40: 開発者向けツール、日本語特化 | F40: Llama等を日本語で追加学習 日本語の読み書き性能が高い オープン公開 研究・業務で利用可 | G40: 完全無料 | H40: 無料で利用可能 | I40: ◯
...

Sheet カテゴリ一覧
A1: カテゴリ名（このとおりに入力） | B1: 説明 | C1: 登録数
A2: よく使われるAIのTOP10 | B2: 世界で実際によく使われているAIを10個選んだものです。何から試せばいいか迷ったら、まずここから。 | C2: =COUNTIF('AIツール一覧'!$E$2:$E$1996,"*"&A2&"*") -> 10
A3: パーソナルアシスタント | B3: 会話でなんでも頼める、いわゆる「AIチャット」です。用途が決まっていないときの万能型です。 | C3: =COUNTIF('AIツール一覧'!$E$2:$E$1996,"*"&A3&"*") -> 31
A4: 情報検索・リサーチ | B4: Webを検索して最新情報を集め、情報元のリンク付きで答えてくれるAIです。 | C4: =COUNTIF('AIツール一覧'!$E$2:$E$1996,"*"&A4&"*") -> 25
A5: ノーコードでアプリ作成 | B5: プログラミングを知らなくても、文章で指示するだけでアプリやWebサイトを作れるAIです。 | C5: =COUNTIF('AIツール一覧'!$E$2:$E$1996,"*"&A5&"*") -> 18
A6: 開発者向けツール | B6: プログラムを書ける人が、AIを使ったシステムを作るための部品や道具です。 | C6: =COUNTIF('AIツール一覧'!$E$2:$E$1996,"*"&A6&"*") -> 49
A7: コード補完 | B7: プログラムを書いている途中で、AIが続きを予測して提案してくれます。 | C7: =COUNTIF('AIツール一覧'!$E$2:$E$1996,"*"&A7&"*") -> 20
A8: Android開発 | B8: Androidアプリ作りに役立つAIです。Android StudioやKotlinに対応しています。 | C8: =COUNTIF('AIツール一覧'!$E$2:$E$1996,"*"&A8&"*") -> 7
A9: ゲーム開発 | B9: キャラクターや3Dの素材作り、ゲームそのものの作成に役立つAIです。 | C9: =COUNTIF('AIツール一覧'!$E$2:$E$1996,"*"&A9&"*") -> 8
A10: 画像作成 | B10: 文章で指示すると、イラストや写真のような画像をゼロから作るAIです。 | C10: =COUNTIF('AIツール一覧'!$E$2:$E$1996,"*"&A10&"*") -> 39
A11: 画像編集 | B11: すでにある写真や画像を加工するAIです。背景除去、不要物の消去、高画質化など。 | C11: =COUNTIF('AIツール一覧'!$E$2:$E$1996,"*"&A11&"*") -> 24
A12: 3Dモデル生成 | B12: 文章や画像から、立体的な3Dデータを作るAIです。 | C12: =COUNTIF('AIツール一覧'!$E$2:$E$1996,"*"&A12&"*") -> 6
A13: 動画作成 | B13: 映像の生成、AIアバターが話す動画、撮った動画の編集などができるAIです。 | C13: =COUNTIF('AIツール一覧'!$E$2:$E$1996,"*"&A13&"*") -> 34
... A28: 日本語特化 | B28: 日本の会社が作ったAIや、日本語に特に強いAIです。 | C28: =COUNTIF('AIツール一覧'!$E$2:$E$1996,"*"&A28&"*") -> 18
